Workbook

Sheet READ ME
A1: Pickleball Fees Tracker (with Per-Player Attendance)
A3: How to use in Google Sheets: 1) In the Settings sheet, confirm fees and Starting Balance. 2) Log each session on the Sessions sheet (Date, Hours, Players). Player Revenue auto-calculates pro‑rata by hours. • 2h session at $5 → full $5 per player; 1h session → $2.50 per player. 3) Track who played on the Attendance sheet: Date, Hours, Player Name, Present (1/0). 4) See Summary by Player for totals per person; Monthly Summary shows costs, net, and carryover. Tip: Next month, set Settings → Starting Balance to last month’s Carryover.

Sheet Settings
A1: Parameter | B1: Value
A2: Monthly Membership Fee | B2: 70
A3: Court Cost per Hour | B3: 12
A4: Player Rate per 2-hour Session | B4: 5
A6: Starting Balance (Carry-in) | B6: 0

Sheet Sessions
A1: Date | B1: Hours (1 or 2) | C1: Players (2-10) | D1: Player Rate (auto) | E1: Player Revenue (pro‑rated) | F1: Court Cost | G1: Net for Session | H1: Running Balance
A2: 45931 | B2: 2 | C2: 7 | D2: =Settings!$B$4 -> 5 | E2: =C2*D2*(B2/2) -> 35 | F2: =B2*Settings!$B$3 -> 24 | G2: =E2-F2 -> 11 | H2: =Settings!$B$6+G2 -> 11
A3: 45938 | B3: 2 | C3: 8 | D3: =Settings!$B$4 -> 5 | E3: =C3*D3*(B3/2) -> 40 | F3: =B3*Settings!$B$3 -> 24 | G3: =E3-F3 -> 16 | H3: =H2+G3 -> 27
A4: 45939 | B4: 2 | C4: 6 | D4: =Settings!$B$4 -> 5 | E4: =C4*D4*(B4/2) -> 30 | F4: =B4*Settings!$B$3 -> 24 | G4: =E4-F4 -> 6 | H4: =H3+G4 -> 33
A5: 45942 | B5: 2 | C5: 6 | D5: =Settings!$B$4 -> 5 | E5: =C5*D5*(B5/2) -> 30 | F5: =B5*Settings!$B$3 -> 24 | G5: =E5-F5 -> 6 | H5: =H4+G5 -> 39
A6: 45945 | B6: 2 | C6: 6 | D6: =Settings!$B$4 -> 5 | E6: =C6*D6*(B6/2) -> 30 | F6: =B6*Settings!$B$3 -> 24 | G6: =E6-F6 -> 6 | H6: =H5+G6 -> 45
A7: 45946 | B7: 2 | C7: 5 | D7: =Settings!$B$4 -> 5 | E7: =C7*D7*(B7/2) -> 25 | F7: =B7*Settings!$B$3 -> 24 | G7: =E7-F7 -> 1 | H7: =H6+G7 -> 46
A8: 45949 | B8: 2 | C8: 4 | D8: =Settings!$B$4 -> 5 | E8: =C8*D8*(B8/2) -> 20 | F8: =B8*Settings!$B$3 -> 24 | G8: =E8-F8 -> -4 | H8: =H7+G8 -> 42
A9: 45952 | B9: 2 | C9: 7 | D9: =Settings!$B$4 -> 5 | E9: =C9*D9*(B9/2) -> 35 | F9: =B9*Settings!$B$3 -> 24 | G9: =E9-F9 -> 11 | H9: =H8+G9 -> 53
A10: 45953 | B10: 2 | C10: 6 | D10: =Settings!$B$4 -> 5 | E10: =C10*D10*(B10/2) -> 30 | F10: =B10*Settings!$B$3 -> 24 | G10: =E10-F10 -> 6 | H10: =H9+G10 -> 59
A11: 45956 | B11: 2 | C11: 10 | D11: =Settings!$B$4 -> 5 | E11: =C11*D11*(B11/2) -> 50 | F11: =B11*Settings!$B$3 -> 24 | G11: =E11-F11 -> 26 | H11: =H10+G11 -> 85
A12: 45960 | B12: 2 | C12: 5 | D12: =Settings!$B$4 -> 5 | E12: =C12*D12*(B12/2) -> 25 | F12: =B12*Settings!$B$3 -> 24 | G12: =E12-F12 -> 1 | H12: =H11+G12 -> 86
D13: =Settings!$B$4 -> 5 | E13: =C13*D13*(B13/2) -> 0 | F13: =B13*Settings!$B$3 -> 0 | G13: =E13-F13 -> 0 | H13: =H12+G13 -> 86
D14: =Settings!$B$4 -> 5 | E14: =C14*D14*(B14/2) -> 0 | F14: =B14*Settings!$B$3 -> 0 | G14: =E14-F14 -> 0 | H14: =H13+G14 -> 86
D15: =Settings!$B$4 -> 5 | E15: =C15*D15*(B15/2) -> 0 | F15: =B15*Settings!$B$3 -> 0 | G15: =E15-F15 -> 0 | H15: =H14+G15 -> 86
D16: =Settings!$B$4 -> 5 | E16: =C16*D16*(B16/2) -> 0 | F16: =B16*Settings!$B$3 -> 0 | G16: =E16-F16 -> 0 | H16: =H15+G16 -> 86
D17: =Settings!$B$4 -> 5 | E17: =C17*D17*(B17/2) -> 0 | F17: =B17*Settings!$B$3 -> 0 | G17: =E17-F17 -> 0 | H17: =H16+G17 -> 86
D18: =Settings!$B$4 -> 5 | E18: =C18*D18*(B18/2) -> 0 | F18: =B18*Settings!$B$3 -> 0 | G18: =E18-F18 -> 0 | H18: =H17+G18 -> 86
D19: =Settings!$B$4 -> 5 | E19: =C19*D19*(B19/2) -> 0 | F19: =B19*Settings!$B$3 -> 0 | G19: =E19-F19 -> 0 | H19: =H18+G19 -> 86
D20: =Settings!$B$4 -> 5 | E20: =C20*D20*(B20/2) -> 0 | F20: =B20*Settings!$B$3 -> 0 | G20: =E20-F20 -> 0 | H20: =H19+G20 -> 86
D21: =Settings!$B$4 -> 5 | E21: =C21*D21*(B21/2) -> 0 | F21: =B21*Settings!$B$3 -> 0 | G21: =E21-F21 -> 0 | H21: =H20+G21 -> 86
D22: =Settings!$B$4 -> 5 | E22: =C22*D22*(B22/2) -> 0 | F22: =B22*Settings!$B$3 -> 0 | G22: =E22-F22 -> 0 | H22: =H21+G22 -> 86
D23: =Settings!$B$4 -> 5 | E23: =C23*D23*(B23/2) -> 0 | F23: =B23*Settings!$B$3 -> 0 | G23: =E23-F23 -> 0 | H23: =H22+G23 -> 86
D24: =Settings!$B$4 -> 5 | E24: =C24*D24*(B24/2) -> 0 | F24: =B24*Settings!$B$3 -> 0 | G24: =E24-F24 -> 0 | H24: =H23+G24 -> 86
... D35: =Settings!$B$4 -> 5 | E35: =C35*D35*(B35/2) -> 0 | F35: =B35*Settings!$B$3 -> 0 | G35: =E35-F35 -> 0 | H35: =H34+G35 -> 86
D36: 5 | E36: =C36*D36*(B36/2) -> 0 | F36: =B36*Settings!$B$3 -> 0 | G36: =E36-F36 -> 0 | H36: =H35+G36 -> 86
D37: =Settings!$B$4 -> 5 | E37: =C37*D37*(B37/2) -> 0 | F37: =B37*Settings!$B$3 -> 0 | G37: =E37-F37 -> 0 | H37: =H36+G37 -> 86
D38: =Settings!$B$4 -> 5 | E38: =C38*D38*(B38/2) -> 0 | F38: =B38*Settings!$B$3 -> 0 | G38: =E38-F38 -> 0 | H38: =H37+G38 -> 86
D39: =Settings!$B$4 -> 5 | E39: =C39*D39*(B39/2) -> 0 | F39: =B39*Settings!$B$3 -> 0 | G39: =E39-F39 -> 0 | H39: =H38+G39 -> 86
D40: =Settings!$B$4 -> 5 | E40: =C40*D40*(B40/2) -> 0 | F40: =B40*Settings!$B$3 -> 0 | G40: =E40-F40 -> 0 | H40: =H39+G40 -> 86
D41: =Settings!$B$4 -> 5 | E41: =C41*D41*(B41/2) -> 0 | F41: =B41*Settings!$B$3 -> 0 | G41: =E41-F41 -> 0 | H41: =H40+G41 -> 86
D42: =Settings!$B$4 -> 5 | E42: =C42*D42*(B42/2) -> 0 | F42: =B42*Settings!$B$3 -> 0 | G42: =E42-F42 -> 0 | H42: =H41+G42 -> 86
D43: =Settings!$B$4 -> 5 | E43: =C43*D43*(B43/2) -> 0 | F43: =B43*Settings!$B$3 -> 0 | G43: =E43-F43 -> 0 | H43: =H42+G43 -> 86
D44: =Settings!$B$4 -> 5 | E44: =C44*D44*(B44/2) -> 0 | F44: =B44*Settings!$B$3 -> 0 | G44: =E44-F44 -> 0 | H44: =H43+G44 -> 86
D45: =Settings!$B$4 -> 5 | E45: =C45*D45*(B45/2) -> 0 | F45: =B45*Settings!$B$3 -> 0 | G45: =E45-F45 -> 0 | H45: =H44+G45 -> 86
D46: =Settings!$B$4 -> 5 | E46: =C46*D46*(B46/2) -> 0 | F46: =B46*Settings!$B$3 -> 0 | G46: =E46-F46 -> 0 | H46: =H45+G46 -> 86
D47: =Settings!$B$4 -> 5 | E47: =C47*D47*(B47/2) -> 0 | F47: =B47*Settings!$B$3 -> 0 | G47: =E47-F47 -> 0 | H47: =H46+G47 -> 86
D48: =Settings!$B$4 -> 5 | E48: =C48*D48*(B48/2) -> 0 | F48: =B48*Settings!$B$3 -> 0 | G48: =E48-F48 -> 0 | H48: =H47+G48 -> 86
... D121: =Settings!$B$4 -> 5 | E121: =C121*D121*(B121/2) -> 0 | F121: =B121*Settings!$B$3 -> 0 | G121: =E121-F121 -> 0 | H121: =H120+G121 -> 86

Sheet Attendance
A1: Date | B1: Hours | C1: Player Name | D1: Present (1/0) | E1: Charge (auto) | F1: PAID
A2: 45931 | B2: 2 | C2: Jay | D2: 1 | E2: =D2*(B2/2)*Settings!$B$4 -> 5 | F2: TRUE
A3: 45931 | B3: 2 | C3: Cora | D3: 1 | E3: =D3*(B3/2)*Settings!$B$4 -> 5 | F3: TRUE
A4: 45931 | B4: 2 | C4: Randy | D4: 1 | E4: =D4*(B4/2)*Settings!$B$4 -> 5 | F4: TRUE
A5: 45931 | B5: 2 | C5: Marv | D5: 1 | E5: =D5*(B5/2)*Settings!$B$4 -> 5 | F5: TRUE
A6: 45931 | B6: 2 | C6: Jenn | D6: 1 | E6: =D6*(B6/2)*Settings!$B$4 -> 5 | F6: TRUE
A7: 45931 | B7: 2 | C7: Christina | D7: 1 | E7: =D7*(B7/2)*Settings!$B$4 -> 5 | F7: TRUE
A8: 45931 | B8: 2 | C8: Zariyan | D8: 1 | E8: =D8*(B8/2)*Settings!$B$4 -> 5 | F8: TRUE
A9: 45938 | B9: 2 | C9: Jay | D9: 1 | E9: =D9*(B9/2)*Settings!$B$4 -> 5 | F9: TRUE
A10: 45938 | B10: 2 | C10: Cora | D10: 1 | E10: =D10*(B10/2)*Settings!$B$4 -> 5 | F10: TRUE
A11: 45938 | B11: 2 | C11: Randy | D11: 1 | E11: =D11*(B11/2)*Settings!$B$4 -> 5 | F11: TRUE
A12: 45938 | B12: 2 | C12: Jenn | D12: 1 | E12: =D12*(B12/2)*Settings!$B$4 -> 5 | F12: TRUE
A13: 45938 | B13: 2 | C13: Marv | D13: 1 | E13: =D13*(B13/2)*Settings!$B$4 -> 5 | F13: TRUE
... A56: 45953 | B56: 2 | C56: Randy | D56: 1 | E56: =D56*(B56/2)*Settings!$B$4 -> 5 | F56: TRUE
A57: 45953 | B57: 2 | D57: 0 | E57: =D57*(B57/2)*Settings!$B$4 -> 0 | F57: FALSE
A58: 45956 | B58: 2 | C58: Jay | D58: 1 | E58: =D58*(B58/2)*Settings!$B$4 -> 5 | F58: TRUE
A59: 45956 | B59: 2 | C59: Cora | D59: 1 | E59: =D59*(B59/2)*Settings!$B$4 -> 5 | F59: TRUE
A60: 45956 | B60: 2 | C60: Jenn | D60: 1 | E60: =D60*(B60/2)*Settings!$B$4 -> 5 | F60: TRUE
A61: 45956 | B61: 2 | C61: Randy | D61: 1 | E61: =D61*(B61/2)*Settings!$B$4 -> 5 | F61: TRUE
A62: 45956 | B62: 2 | C62: Carmela | D62: 1 | E62: =D62*(B62/2)*Settings!$B$4 -> 5 | F62: TRUE
A63: 45956 | B63: 2 | C63: Marv | D63: 1 | E63: =D63*(B63/2)*Settings!$B$4 -> 5 | F63: TRUE
A64: 45956 | B64: 2 | C64: JoeO | D64: 1 | E64: =D64*(B64/2)*Settings!$B$4 -> 5 | F64: TRUE
A65: 45956 | B65: 2 | C65: Arman | D65: 1 | E65: =D65*(B65/2)*Settings!$B$4 -> 5 | F65: TRUE
A66: 45956 | B66: 2 | C66: Rhon | D66: 1 | E66: =D66*(B66/2)*Settings!$B$4 -> 5 | F66: TRUE
A67: 45956 | B67: 2 | C67: Marie | D67: 1 | E67: =D67*(B67/2)*Settings!$B$4 -> 5 | F67: TRUE
A68: 45960 | B68: 2 | C68: Jay | D68: 1 | E68: =D68*(B68/2)*Settings!$B$4 -> 5 | F68: FALSE
A69: 45960 | B69: 2 | C69: Randy | D69: 1 | E69: =D69*(B69/2)*Settings!$B$4 -> 5 | F69: TRUE
... A72: 45960 | B72: 2 | C72: Trevor | D72: 1 | E72: =D72*(B72/2)*Settings!$B$4 -> 5 | F72: FALSE
E73: =D73*(B73/2)*Settings!$B$4 -> 0 | F73: FALSE
E74: =D74*(B74/2)*Settings!$B$4 -> 0 | F74: FALSE
E75: =D75*(B75/2)*Settings!$B$4 -> 0 | F75: FALSE
E76: =D76*(B76/2)*Settings!$B$4 -> 0 | F76: FALSE
E77: =D77*(B77/2)*Settings!$B$4 -> 0 | F77: FALSE
E78: =D78*(B78/2)*Settings!$B$4 -> 0 | F78: FALSE
E79: =D79*(B79/2)*Settings!$B$4 -> 0 | F79: FALSE
E80: =D80*(B80/2)*Settings!$B$4 -> 0 | F80: FALSE
E81: =D81*(B81/2)*Settings!$B$4 -> 0 | F81: FALSE
E82: =D82*(B82/2)*Settings!$B$4 -> 0 | F82: FALSE
E83: =D83*(B83/2)*Settings!$B$4 -> 0 | F83: FALSE
E84: =D84*(B84/2)*Settings!$B$4 -> 0 | F84: FALSE
...

Sheet Summary by Player
A1: =IFERROR(__xludf.DUMMYFUNCTION("QUERY( Attendance!C2:E1000, ""select C, sum(D), sum(E) where C is not null group by C label C 'Player', sum(D) 'Sessions Attended', sum(E) 'Total Charges'"", 0 )"),"Player") -> Player | B1: =IFERROR(__xludf.DUMMYFUNCTION("""COMPUTED_VALUE"""),"Sessions Attended") -> Sessions Attended | C1: =IFERROR(__xludf.DUMMYFUNCTION("""COMPUTED_VALUE"""),"Total Charges") -> Total Charges
A2: =IFERROR(__xludf.DUMMYFUNCTION("""COMPUTED_VALUE"""),"Arman") -> Arman | B2: =IFERROR(__xludf.DUMMYFUNCTION("""COMPUTED_VALUE"""),4.0) -> 4 | C2: =IFERROR(__xludf.DUMMYFUNCTION("""COMPUTED_VALUE"""),20.0) -> 20
A3: =IFERROR(__xludf.DUMMYFUNCTION("""COMPUTED_VALUE"""),"Carmela") -> Carmela | B3: =IFERROR(__xludf.DUMMYFUNCTION("""COMPUTED_VALUE"""),8.0) -> 8 | C3: =IFERROR(__xludf.DUMMYFUNCTION("""COMPUTED_VALUE"""),40.0) -> 40
A4: =IFERROR(__xludf.DUMMYFUNCTION("""COMPUTED_VALUE"""),"Christina") -> Christina | B4: =IFERROR(__xludf.DUMMYFUNCTION("""COMPUTED_VALUE"""),2.0) -> 2 | C4: =IFERROR(__xludf.DUMMYFUNCTION("""COMPUTED_VALUE"""),10.0) -> 10
A5: =IFERROR(__xludf.DUMMYFUNCTION("""COMPUTED_VALUE"""),"Cora") -> Cora | B5: =IFERROR(__xludf.DUMMYFUNCTION("""COMPUTED_VALUE"""),6.0) -> 6 | C5: =IFERROR(__xludf.DUMMYFUNCTION("""COMPUTED_VALUE"""),30.0) -> 30
A6: =IFERROR(__xludf.DUMMYFUNCTION("""COMPUTED_VALUE"""),"Jay ") -> Jay | B6: =IFERROR(__xludf.DUMMYFUNCTION("""COMPUTED_VALUE"""),10.0) -> 10 | C6: =IFERROR(__xludf.DUMMYFUNCTION("""COMPUTED_VALUE"""),50.0) -> 50
A7: =IFERROR(__xludf.DUMMYFUNCTION("""COMPUTED_VALUE"""),"Jenn") -> Jenn | B7: =IFERROR(__xludf.DUMMYFUNCTION("""COMPUTED_VALUE"""),8.0) -> 8 | C7: =IFERROR(__xludf.DUMMYFUNCTION("""COMPUTED_VALUE"""),40.0) -> 40
A8: =IFERROR(__xludf.DUMMYFUNCTION("""COMPUTED_VALUE"""),"JoeO") -> JoeO | B8: =IFERROR(__xludf.DUMMYFUNCTION("""COMPUTED_VALUE"""),3.0) -> 3 | C8: =IFERROR(__xludf.DUMMYFUNCTION("""COMPUTED_VALUE"""),15.0) -> 15
A9: =IFERROR(__xludf.DUMMYFUNCTION("""COMPUTED_VALUE"""),"Jon") -> Jon | B9: =IFERROR(__xludf.DUMMYFUNCTION("""COMPUTED_VALUE"""),1.0) -> 1 | C9: =IFERROR(__xludf.DUMMYFUNCTION("""COMPUTED_VALUE"""),5.0) -> 5
A10: =IFERROR(__xludf.DUMMYFUNCTION("""COMPUTED_VALUE"""),"Marie") -> Marie | B10: =IFERROR(__xludf.DUMMYFUNCTION("""COMPUTED_VALUE"""),1.0) -> 1 | C10: =IFERROR(__xludf.DUMMYFUNCTION("""COMPUTED_VALUE"""),5.0) -> 5
A11: =IFERROR(__xludf.DUMMYFUNCTION("""COMPUTED_VALUE"""),"Marv") -> Marv | B11: =IFERROR(__xludf.DUMMYFUNCTION("""COMPUTED_VALUE"""),10.0) -> 10 | C11: =IFERROR(__xludf.DUMMYFUNCTION("""COMPUTED_VALUE"""),50.0) -> 50
A12: =IFERROR(__xludf.DUMMYFUNCTION("""COMPUTED_VALUE"""),"Randy") -> Randy | B12: =IFERROR(__xludf.DUMMYFUNCTION("""COMPUTED_VALUE"""),9.0) -> 9 | C12: =IFERROR(__xludf.DUMMYFUNCTION("""COMPUTED_VALUE"""),45.0) -> 45
A13: =IFERROR(__xludf.DUMMYFUNCTION("""COMPUTED_VALUE"""),"Rhon") -> Rhon | B13: =IFERROR(__xludf.DUMMYFUNCTION("""COMPUTED_VALUE"""),1.0) -> 1 | C13: =IFERROR(__xludf.DUMMYFUNCTION("""COMPUTED_VALUE"""),5.0) -> 5
A14: =IFERROR(__xludf.DUMMYFUNCTION("""COMPUTED_VALUE"""),"Tony") -> Tony | B14: =IFERROR(__xludf.DUMMYFUNCTION("""COMPUTED_VALUE"""),1.0) -> 1 | C14: =IFERROR(__xludf.DUMMYFUNCTION("""COMPUTED_VALUE"""),5.0) -> 5
A15: =IFERROR(__xludf.DUMMYFUNCTION("""COMPUTED_VALUE"""),"Trevor") -> Trevor | B15: =IFERROR(__xludf.DUMMYFUNCTION("""COMPUTED_VALUE"""),4.0) -> 4 | C15: =IFERROR(__xludf.DUMMYFUNCTION("""COMPUTED_VALUE"""),20.0) -> 20
A16: =IFERROR(__xludf.DUMMYFUNCTION("""COMPUTED_VALUE"""),"Zariyan") -> Zariyan | B16: =IFERROR(__xludf.DUMMYFUNCTION("""COMPUTED_VALUE"""),2.0) -> 2 | C16: =IFERROR(__xludf.DUMMYFUNCTION("""COMPUTED_VALUE"""),10.0) -> 10

Sheet Monthly Summary
A3: Metric | B3: Value
A4: Total Sessions | B4: =COUNTA(Sessions!A2:A1000000) -> 11
A5: Total Hours | B5: =SUM(Sessions!B2:B1000000) -> 22
A6: Total Player Revenue | B6: =SUM(Sessions!E2:E1000000) -> 350
A7: Total Court Cost | B7: =SUM(Sessions!F2:F1000000) -> 264
A8: Membership Fee | B8: =Settings!$B$2 -> 70
A9: Net (Revenue - Court - Membership) | B9: =B6-B7-B8 -> 16
A10: Carryover to Next Month | B10: =B9 -> 16
